Workbook

Sheet Timeline
A1: Yehezkiel's PhD Timeline - ANU RSES (3-year plan)
A3: Enrolment start date | D3: 46294
A4: Year 1 Plan + Candidate-Supervisor Agreement due | D4: =H24 -> 46384
A5: Confirmation of Candidature (oral) target - month 9 (latest allowed: month 12) | D5: =H34 -> 46566
A6: Final seminar to School (6 months before submission) | D6: =H48 -> 47205
A7: Target Thesis Submission (3 years) | D7: =H55 -> 47389
A8: Scholarship program end (3.5 years) | D8: =EDATE($D$3,42)-1 -> 47570
A9: Maximum Enrolment Period, MEP (4 years) | D9: =EDATE($D$3,48)-1 -> 47754
A10: Maximum Period for Completion, MPC (5 years) | D10: =EDATE($D$3,60)-1 -> 48119
A11: Progress (tasks marked Done) | D11: =COUNTIF(J14:J57,"Done")/COUNTA(A14:A57) -> 0.022727273
A13: ID | B13: Phase | C13: Task | D13: Type | E13: Start M | F13: End M | G13: Start date | H13: End date (due) | I13: Owner | J13: Status | K13: Notes
A14: T01 | B14: 0 Onboarding (M1-3) | C14: ANU mandatory: Rights, Relationships & Respect in Research | D14: Task | E14: 1 | F14: 2 | G14: =EDATE($D$3,E14-1) -> 46294 | H14: =EDATE($D$3,F14)-1 -> 46354 | I14: Me | J14: Not started | K14: ANU requirement in first 3 months
A15: T02 | B15: 0 Onboarding (M1-3) | C15: ANU mandatory: CORE Cultural Learning | D15: Task | E15: 1 | F15: 2 | G15: =EDATE($D$3,E15-1) -> 46294 | H15: =EDATE($D$3,F15)-1 -> 46354 | I15: Me | J15: Not started
A16: T03 | B16: 0 Onboarding (M1-3) | C16: ANU mandatory: University Work Health & Safety (WHS) induction | D16: Task | E16: 1 | F16: 2 | G16: =EDATE($D$3,E16-1) -> 46294 | H16: =EDATE($D$3,F16)-1 -> 46354 | I16: Me | J16: In progress
A17: T04 | B17: 0 Onboarding (M1-3) | C17: ANU mandatory: Code of Conduct | D17: Task | E17: 1 | F17: 2 | G17: =EDATE($D$3,E17-1) -> 46294 | H17: =EDATE($D$3,F17)-1 -> 46354 | I17: Me | J17: In progress
A18: T05 | B18: 0 Onboarding (M1-3) | C18: Research integrity training | D18: Task | E18: 1 | F18: 3 | G18: =EDATE($D$3,E18-1) -> 46294 | H18: =EDATE($D$3,F18)-1 -> 46384 | I18: Me | J18: In progress
A19: T06 | B19: 0 Onboarding (M1-3) | C19: RSES induction + local WHS (whs.rses@anu.edu.au) | D19: Task | E19: 1 | F19: 2 | G19: =EDATE($D$3,E19-1) -> 46294 | H19: =EDATE($D$3,F19)-1 -> 46354 | I19: Me | J19: Not started
A20: T07 | B20: 0 Onboarding (M1-3) | C20: Set up supervisory panel (Chair + advisors) | D20: Task | E20: 1 | F20: 2 | G20: =EDATE($D$3,E20-1) -> 46294 | H20: =EDATE($D$3,F20)-1 -> 46354 | I20: Me + Supervisor | J20: Not started
A21: T08 | B21: 0 Onboarding (M1-3) | C21: Agree expectations with supervisor: feedback turnaround, hours (40 h/wk), WFH vs on-campus, etc | D21: Task | E21: 1 | F21: 1 | G21: =EDATE($D$3,E21-1) -> 46294 | H21: =EDATE($D$3,F21)-1 -> 46323 | I21: Me + Supervisor | J21: Delayed | K21: Common source of misunderstanding - settle early and in writing
A22: T09 | B22: 0 Onboarding (M1-3) | C22: Order computer (up to $2k; supervisor emails HDR Admin if > $2k) | D22: Task | E22: 1 | F22: 2 | G22: =EDATE($D$3,E22-1) -> 46294 | H22: =EDATE($D$3,F22)-1 -> 46354 | I22: Me + Supervisor | J22: Not started | K22: Robyne Anderson orders through IT
A23: T10 | B23: 0 Onboarding (M1-3) | C23: Check milestones in ANUHub (selfservice.sas.anu.edu.au) and eForms | D23: Task | E23: 1 | F23: 1 | G23: =EDATE($D$3,E23-1) -> 46294 | H23: =EDATE($D$3,F23)-1 -> 46323 | I23: Me | J23: Done | K23: Students check ANUHub; supervisors check ANUHub & eForms
A24: T11 | B24: 0 Onboarding (M1-3) | C24: Submit Candidate-Supervisor Agreement + Year 1 Plan | D24: Milestone | E24: 3 | F24: 3 | G24: =EDATE($D$3,E24-1) -> 46355 | H24: =EDATE($D$3,F24)-1 -> 46384 | I24: Me + Supervisor | J24: Not started | K24: Required for 1st Annual Plan. Revisit the Agreement every year, do not 'set & forget'
A25: T12 | B25: 1 Foundation & Confirmation (M1-12) | C25: Literature review | D25: Task | E25: 1 | F25: 6 | G25: =EDATE($D$3,E25-1) -> 46294 | H25: =EDATE($D$3,F25)-1 -> 46474 | I25: Me | J25: Not started | K25: Feeds the CoC thesis proposal
A26: T13 | B26: 1 Foundation & Confirmation (M1-12) | C26: Skills assessment & training plan (part of CoC written component) | D26: Task | E26: 2 | F26: 4 | G26: =EDATE($D$3,E26-1) -> 46324 | H26: =EDATE($D$3,F26)-1 -> 46415 | I26: Me + Supervisor | J26: Not started | K26: Basis for professional development discussion
A27: T14 | B27: 1 Foundation & Confirmation (M1-12) | C27: Develop methodology / pilot tests | D27: Task | E27: 3 | F27: 8 | G27: =EDATE($D$3,E27-1) -> 46355 | H27: =EDATE($D$3,F27)-1 -> 46535 | I27: Me | J27: Not started
A28: T15 | B28: 1 Foundation & Confirmation (M1-12) | C28: Initial results / progress towards results | D28: Task | E28: 5 | F28: 8 | G28: =EDATE($D$3,E28-1) -> 46416 | H28: =EDATE($D$3,F28)-1 -> 46535 | I28: Me | J28: Not started | K28: CoC written component must include initial results
A29: T16 | B29: 1 Foundation & Confirmation (M1-12) | C29: Confirmation Review Panel (CRP) established by Delegated Authority / AD(HDR) | D29: Milestone | E29: 4 | F29: 4 | G29: =EDATE($D$3,E29-1) -> 46385 | H29: =EDATE($D$3,F29)-1 -> 46415 | I29: AD(HDR) | J29: Not started | K29: Follows First Year Plan (+/- 3 months)
A30: T17 | B30: 1 Foundation & Confirmation (M1-12) | C30: Write Thesis Proposal (min 4,000 words: lit review, method, original contribution, initial results, timeline, resources, skills assessment) | D30: Task | E30: 6 | F30: 8 | G30: =EDATE($D$3,E30-1) -> 46446 | H30: =EDATE($D$3,F30)-1 -> 46535 | I30: Me | J30: Not started | K30: Prepared with supervisory panel
A31: T18 | B31: 1 Foundation & Confirmation (M1-12) | C31: Primary Supervisor approves proposal; submit to CRP (>= 10 working days before oral) | D31: Milestone | E31: 8 | F31: 8 | G31: =EDATE($D$3,E31-1) -> 46506 | H31: =EDATE($D$3,F31)-1 -> 46535 | I31: Me + Supervisor | J31: Not started | K31: Hard rule: at least 10 working days before oral presentation
A32: T19 | B32: 1 Foundation & Confirmation (M1-12) | C32: CRP Chair greeting / meeting with candidate (1 month prior to CoC) | D32: Milestone | E32: 8 | F32: 8 | G32: =EDATE($D$3,E32-1) -> 46506 | H32: =EDATE($D$3,F32)-1 -> 46535 | I32: CRP Chair | J32: Not started
A33: T20 | B33: 1 Foundation & Confirmation (M1-12) | C33: Prepare CoC oral presentation (20-30 min + up to 20 min discussion) | D33: Task | E33: 8 | F33: 9 | G33: =EDATE($D$3,E33-1) -> 46506 | H33: =EDATE($D$3,F33)-1 -> 46566 | I33: Me | J33: Not started | K33: Open to all RSES; all CRP members must attend
A34: T21 | B34: 1 Foundation & Confirmation (M1-12) | C34: CoC oral presentation - aim for EARLIER time (month 9) | D34: Milestone | E34: 9 | F34: 9 | G34: =EDATE($D$3,E34-1) -> 46536 | H34: =EDATE($D$3,F34)-1 -> 46566 | I34: Me | J34: Not started | K34: PhD window is 9(-12) months. Deck asks students to aim for the earlier time so amendments still fit
A35: T22 | B35: 1 Foundation & Confirmation (M1-12) | C35: CRP outcome / amendments window (to month 12 latest) | D35: Task | E35: 9 | F35: 12 | G35: =EDATE($D$3,E35-1) -> 46536 | H35: =EDATE($D$3,F35)-1 -> 46658 | I35: CRP / Me | J35: Not started | K35: Outcomes: continue, convert, withdraw, discontinue; amendments -> further CRP review
A36: T23 | B36: 1 Foundation & Confirmation (M1-12) | C36: Attend RSES Thursday seminars (13:00-14:00, J1) and ask questions | D36: Task | E36: 1 | F36: 9 | G36: =EDATE($D$3,E36-1) -> 46294 | H36: =EDATE($D$3,F36)-1 -> 46566 | I36: Me | J36: Not started | K36: Attendance expected as part of CoC; keep going afterwards
A37: T24 | B37: 2 Core research (M9-26) | C37: Year 2 Annual Report / Plan (eForm, bullets, < 2 pages) | D37: Milestone | E37: 12 | F37: 12 | G37: =EDATE($D$3,E37-1) -> 46628 | H37: =EDATE($D$3,F37)-1 -> 46658 | I37: Me + Chair | J37: Not started | K37: Discuss with supervisor/Chair & advisory committee before submitting. If CoC slips near this date, submit together and refer to CoC
A38: T25 | B38: 2 Core research (M9-26) | C38: Main analysis / method application - part 1 | D38: Task | E38: 9 | F38: 18 | G38: =EDATE($D$3,E38-1) -> 46536 | H38: =EDATE($D$3,F38)-1 -> 46840 | I38: Me | J38: Not started
A39: T26 | B39: 2 Core research (M9-26) | C39: Paper 1: draft, submit to journal | D39: Task | E39: 10 | F39: 16 | G39: =EDATE($D$3,E39-1) -> 46567 | H39: =EDATE($D$3,F39)-1 -> 46780 | I39: Me + Supervisor | J39: Not started | K39: Reuse in thesis chapters
A40: T27 | B40: 2 Core research (M9-26) | C40: Main analysis - part 2 / validation | D40: Task | E40: 16 | F40: 24 | G40: =EDATE($D$3,E40-1) -> 46750 | H40: =EDATE($D$3,F40)-1 -> 47024 | I40: Me | J40: Not started
A41: T28 | B41: 2 Core research (M9-26) | C41: Conference presentation (travel support up to $5k via AD(HDR); RSES grant deadline 15 March) | D41: Task | E41: 15 | F41: 20 | G41: =EDATE($D$3,E41-1) -> 46720 | H41: =EDATE($D$3,F41)-1 -> 46901 | I41: Me | J41: Not started | K41: Check ANU/RSES travel grants each year
A42: T29 | B42: 2 Core research (M9-26) | C42: Paper 2: draft, submit to journal | D42: Task | E42: 18 | F42: 26 | G42: =EDATE($D$3,E42-1) -> 46812 | H42: =EDATE($D$3,F42)-1 -> 47085 | I42: Me + Supervisor | J42: Not started
...

Sheet Gantt
A1: Gantt - 42 months (36-month plan + 6-month buffer)
G3: Year 1 | S3: Year 2 | AE3: Year 3 | AQ3: Buffer
A4: ID | B4: Phase | C4: Task | D4: Type | E4: Start M | F4: End M | G4: 1 | H4: 2 | I4: 3 | J4: 4 | K4: 5 | L4: 6 | M4: 7 | N4: 8 | O4: 9 | P4: 10 | Q4: 11 | R4: 12 | S4: 13 | T4: 14 | U4: 15 | V4: 16 | W4: 17 | X4: 18 | Y4: 19 | Z4: 20 | AA4: 21 | AB4: 22 | AC4: 23 | AD4: 24 | AE4: 25 | AF4: 26 | AG4: 27 | AH4: 28 | AI4: 29 | AJ4: 30 | AK4: 31 | AL4: 32 | AM4: 33 | AN4: 34 | AO4: 35 | AP4: 36 | AQ4: 37 | AR4: 38 | AS4: 39 | AT4: 40 | AU4: 41 | AV4: 42
G5: =TEXT(EDATE(Timeline!$D$3,G$4-1),"mmm yy") -> Sep 26 | H5: =TEXT(EDATE(Timeline!$D$3,H$4-1),"mmm yy") -> Oct 26 | I5: =TEXT(EDATE(Timeline!$D$3,I$4-1),"mmm yy") -> Nov 26 | J5: =TEXT(EDATE(Timeline!$D$3,J$4-1),"mmm yy") -> Dec 26 | K5: =TEXT(EDATE(Timeline!$D$3,K$4-1),"mmm yy") -> Jan 27 | L5: =TEXT(EDATE(Timeline!$D$3,L$4-1),"mmm yy") -> Feb 27 | M5: =TEXT(EDATE(Timeline!$D$3,M$4-1),"mmm yy") -> Mar 27 | N5: =TEXT(EDATE(Timeline!$D$3,N$4-1),"mmm yy") -> Apr 27 | ... AV5: =TEXT(EDATE(Timeline!$D$3,AV$4-1),"mmm yy") -> Feb 30
A6: =Timeline!A14 -> T01 | B6: =Timeline!B14 -> 0 Onboarding (M1-3) | C6: =Timeline!C14 -> ANU mandatory: Rights, Relationships & Respect in Research | D6: =Timeline!D14 -> Task | E6: =Timeline!E14 -> 1 | F6: =Timeline!F14 -> 2 | G6: =IF(AND(G$4>=$E6,G$4<=$F6),1,"") -> 1 | H6: =IF(AND(H$4>=$E6,H$4<=$F6),1,"") -> 1 | I6: =IF(AND(I$4>=$E6,I$4<=$F6),1,"") | J6: =IF(AND(J$4>=$E6,J$4<=$F6),1,"") | K6: =IF(AND(K$4>=$E6,K$4<=$F6),1,"") | L6: =IF(AND(L$4>=$E6,L$4<=$F6),1,"") | M6: =IF(AND(M$4>=$E6,M$4<=$F6),1,"") | N6: =IF(AND(N$4>=$E6,N$4<=$F6),1,"") | ... AV6: =IF(AND(AV$4>=$E6,AV$4<=$F6),1,"")
A7: =Timeline!A15 -> T02 | B7: =Timeline!B15 -> 0 Onboarding (M1-3) | C7: =Timeline!C15 -> ANU mandatory: CORE Cultural Learning | D7: =Timeline!D15 -> Task | E7: =Timeline!E15 -> 1 | F7: =Timeline!F15 -> 2 | G7: =IF(AND(G$4>=$E7,G$4<=$F7),1,"") -> 1 | H7: =IF(AND(H$4>=$E7,H$4<=$F7),1,"") -> 1 | I7: =IF(AND(I$4>=$E7,I$4<=$F7),1,"") | J7: =IF(AND(J$4>=$E7,J$4<=$F7),1,"") | K7: =IF(AND(K$4>=$E7,K$4<=$F7),1,"") | L7: =IF(AND(L$4>=$E7,L$4<=$F7),1,"") | M7: =IF(AND(M$4>=$E7,M$4<=$F7),1,"") | N7: =IF(AND(N$4>=$E7,N$4<=$F7),1,"") | ... AV7: =IF(AND(AV$4>=$E7,AV$4<=$F7),1,"")
A8: =Timeline!A16 -> T03 | B8: =Timeline!B16 -> 0 Onboarding (M1-3) | C8: =Timeline!C16 -> ANU mandatory: University Work Health & Safety (WHS) induction | D8: =Timeline!D16 -> Task | E8: =Timeline!E16 -> 1 | F8: =Timeline!F16 -> 2 | G8: =IF(AND(G$4>=$E8,G$4<=$F8),1,"") -> 1 | H8: =IF(AND(H$4>=$E8,H$4<=$F8),1,"") -> 1 | I8: =IF(AND(I$4>=$E8,I$4<=$F8),1,"") | J8: =IF(AND(J$4>=$E8,J$4<=$F8),1,"") | K8: =IF(AND(K$4>=$E8,K$4<=$F8),1,"") | L8: =IF(AND(L$4>=$E8,L$4<=$F8),1,"") | M8: =IF(AND(M$4>=$E8,M$4<=$F8),1,"") | N8: =IF(AND(N$4>=$E8,N$4<=$F8),1,"") | ... AV8: =IF(AND(AV$4>=$E8,AV$4<=$F8),1,"")
A9: =Timeline!A17 -> T04 | B9: =Timeline!B17 -> 0 Onboarding (M1-3) | C9: =Timeline!C17 -> ANU mandatory: Code of Conduct | D9: =Timeline!D17 -> Task | E9: =Timeline!E17 -> 1 | F9: =Timeline!F17 -> 2 | G9: =IF(AND(G$4>=$E9,G$4<=$F9),1,"") -> 1 | H9: =IF(AND(H$4>=$E9,H$4<=$F9),1,"") -> 1 | I9: =IF(AND(I$4>=$E9,I$4<=$F9),1,"") | J9: =IF(AND(J$4>=$E9,J$4<=$F9),1,"") | K9: =IF(AND(K$4>=$E9,K$4<=$F9),1,"") | L9: =IF(AND(L$4>=$E9,L$4<=$F9),1,"") | M9: =IF(AND(M$4>=$E9,M$4<=$F9),1,"") | N9: =IF(AND(N$4>=$E9,N$4<=$F9),1,"") | ... AV9: =IF(AND(AV$4>=$E9,AV$4<=$F9),1,"")
A10: =Timeline!A18 -> T05 | B10: =Timeline!B18 -> 0 Onboarding (M1-3) | C10: =Timeline!C18 -> Research integrity training | D10: =Timeline!D18 -> Task | E10: =Timeline!E18 -> 1 | F10: =Timeline!F18 -> 3 | G10: =IF(AND(G$4>=$E10,G$4<=$F10),1,"") -> 1 | H10: =IF(AND(H$4>=$E10,H$4<=$F10),1,"") -> 1 | I10: =IF(AND(I$4>=$E10,I$4<=$F10),1,"") -> 1 | J10: =IF(AND(J$4>=$E10,J$4<=$F10),1,"") | K10: =IF(AND(K$4>=$E10,K$4<=$F10),1,"") | L10: =IF(AND(L$4>=$E10,L$4<=$F10),1,"") | M10: =IF(AND(M$4>=$E10,M$4<=$F10),1,"") | N10: =IF(AND(N$4>=$E10,N$4<=$F10),1,"") | ... AV10: =IF(AND(AV$4>=$E10,AV$4<=$F10),1,"")
A11: =Timeline!A19 -> T06 | B11: =Timeline!B19 -> 0 Onboarding (M1-3) | C11: =Timeline!C19 -> RSES induction + local WHS (whs.rses@anu.edu.au) | D11: =Timeline!D19 -> Task | E11: =Timeline!E19 -> 1 | F11: =Timeline!F19 -> 2 | G11: =IF(AND(G$4>=$E11,G$4<=$F11),1,"") -> 1 | H11: =IF(AND(H$4>=$E11,H$4<=$F11),1,"") -> 1 | I11: =IF(AND(I$4>=$E11,I$4<=$F11),1,"") | J11: =IF(AND(J$4>=$E11,J$4<=$F11),1,"") | K11: =IF(AND(K$4>=$E11,K$4<=$F11),1,"") | L11: =IF(AND(L$4>=$E11,L$4<=$F11),1,"") | M11: =IF(AND(M$4>=$E11,M$4<=$F11),1,"") | N11: =IF(AND(N$4>=$E11,N$4<=$F11),1,"") | ... AV11: =IF(AND(AV$4>=$E11,AV$4<=$F11),1,"")
A12: =Timeline!A20 -> T07 | B12: =Timeline!B20 -> 0 Onboarding (M1-3) | C12: =Timeline!C20 -> Set up supervisory panel (Chair + advisors) | D12: =Timeline!D20 -> Task | E12: =Timeline!E20 -> 1 | F12: =Timeline!F20 -> 2 | G12: =IF(AND(G$4>=$E12,G$4<=$F12),1,"") -> 1 | H12: =IF(AND(H$4>=$E12,H$4<=$F12),1,"") -> 1 | I12: =IF(AND(I$4>=$E12,I$4<=$F12),1,"") | J12: =IF(AND(J$4>=$E12,J$4<=$F12),1,"") | K12: =IF(AND(K$4>=$E12,K$4<=$F12),1,"") | L12: =IF(AND(L$4>=$E12,L$4<=$F12),1,"") | M12: =IF(AND(M$4>=$E12,M$4<=$F12),1,"") | N12: =IF(AND(N$4>=$E12,N$4<=$F12),1,"") | ... AV12: =IF(AND(AV$4>=$E12,AV$4<=$F12),1,"")
A13: =Timeline!A21 -> T08 | B13: =Timeline!B21 -> 0 Onboarding (M1-3) | C13: =Timeline!C21 -> Agree expectations with supervisor: feedback turnaround, hours (40 h/wk), WFH vs on-campus, etc | D13: =Timeline!D21 -> Task | E13: =Timeline!E21 -> 1 | F13: =Timeline!F21 -> 1 | G13: =IF(AND(G$4>=$E13,G$4<=$F13),1,"") -> 1 | H13: =IF(AND(H$4>=$E13,H$4<=$F13),1,"") | I13: =IF(AND(I$4>=$E13,I$4<=$F13),1,"") | J13: =IF(AND(J$4>=$E13,J$4<=$F13),1,"") | K13: =IF(AND(K$4>=$E13,K$4<=$F13),1,"") | L13: =IF(AND(L$4>=$E13,L$4<=$F13),1,"") | M13: =IF(AND(M$4>=$E13,M$4<=$F13),1,"") | N13: =IF(AND(N$4>=$E13,N$4<=$F13),1,"") | ... AV13: =IF(AND(AV$4>=$E13,AV$4<=$F13),1,"")
A14: =Timeline!A22 -> T09 | B14: =Timeline!B22 -> 0 Onboarding (M1-3) | C14: =Timeline!C22 -> Order computer (up to $2k; supervisor emails HDR Admin if > $2k) | D14: =Timeline!D22 -> Task | E14: =Timeline!E22 -> 1 | F14: =Timeline!F22 -> 2 | G14: =IF(AND(G$4>=$E14,G$4<=$F14),1,"") -> 1 | H14: =IF(AND(H$4>=$E14,H$4<=$F14),1,"") -> 1 | I14: =IF(AND(I$4>=$E14,I$4<=$F14),1,"") | J14: =IF(AND(J$4>=$E14,J$4<=$F14),1,"") | K14: =IF(AND(K$4>=$E14,K$4<=$F14),1,"") | L14: =IF(AND(L$4>=$E14,L$4<=$F14),1,"") | M14: =IF(AND(M$4>=$E14,M$4<=$F14),1,"") | N14: =IF(AND(N$4>=$E14,N$4<=$F14),1,"") | ... AV14: =IF(AND(AV$4>=$E14,AV$4<=$F14),1,"")
A15: =Timeline!A23 -> T10 | B15: =Timeline!B23 -> 0 Onboarding (M1-3) | C15: =Timeline!C23 -> Check milestones in ANUHub (selfservice.sas.anu.edu.au) and eForms | D15: =Timeline!D23 -> Task | E15: =Timeline!E23 -> 1 | F15: =Timeline!F23 -> 1 | G15: =IF(AND(G$4>=$E15,G$4<=$F15),1,"") -> 1 | H15: =IF(AND(H$4>=$E15,H$4<=$F15),1,"") | I15: =IF(AND(I$4>=$E15,I$4<=$F15),1,"") | J15: =IF(AND(J$4>=$E15,J$4<=$F15),1,"") | K15: =IF(AND(K$4>=$E15,K$4<=$F15),1,"") | L15: =IF(AND(L$4>=$E15,L$4<=$F15),1,"") | M15: =IF(AND(M$4>=$E15,M$4<=$F15),1,"") | N15: =IF(AND(N$4>=$E15,N$4<=$F15),1,"") | ... AV15: =IF(AND(AV$4>=$E15,AV$4<=$F15),1,"")
A16: =Timeline!A24 -> T11 | B16: =Timeline!B24 -> 0 Onboarding (M1-3) | C16: =Timeline!C24 -> Submit Candidate-Supervisor Agreement + Year 1 Plan | D16: =Timeline!D24 -> Milestone | E16: =Timeline!E24 -> 3 | F16: =Timeline!F24 -> 3 | G16: =IF(AND(G$4>=$E16,G$4<=$F16),1,"") | H16: =IF(AND(H$4>=$E16,H$4<=$F16),1,"") | I16: =IF(AND(I$4>=$E16,I$4<=$F16),1,"") -> 1 | J16: =IF(AND(J$4>=$E16,J$4<=$F16),1,"") | K16: =IF(AND(K$4>=$E16,K$4<=$F16),1,"") | L16: =IF(AND(L$4>=$E16,L$4<=$F16),1,"") | M16: =IF(AND(M$4>=$E16,M$4<=$F16),1,"") | N16: =IF(AND(N$4>=$E16,N$4<=$F16),1,"") | ... AV16: =IF(AND(AV$4>=$E16,AV$4<=$F16),1,"")
A17: =Timeline!A25 -> T12 | B17: =Timeline!B25 -> 1 Foundation & Confirmation (M1-12) | C17: =Timeline!C25 -> Literature review | D17: =Timeline!D25 -> Task | E17: =Timeline!E25 -> 1 | F17: =Timeline!F25 -> 6 | G17: =IF(AND(G$4>=$E17,G$4<=$F17),1,"") -> 1 | H17: =IF(AND(H$4>=$E17,H$4<=$F17),1,"") -> 1 | I17: =IF(AND(I$4>=$E17,I$4<=$F17),1,"") -> 1 | J17: =IF(AND(J$4>=$E17,J$4<=$F17),1,"") -> 1 | K17: =IF(AND(K$4>=$E17,K$4<=$F17),1,"") -> 1 | L17: =IF(AND(L$4>=$E17,L$4<=$F17),1,"") -> 1 | M17: =IF(AND(M$4>=$E17,M$4<=$F17),1,"") | N17: =IF(AND(N$4>=$E17,N$4<=$F17),1,"") | ... AV17: =IF(AND(AV$4>=$E17,AV$4<=$F17),1,"")
... A49: =Timeline!A57 -> T44 | B49: =Timeline!B57 -> 4 Post-submission / buffer | C49: =Timeline!C57 -> Buffer: scholarship program end at 3.5 years (contingency if anything slips) | D49: =Timeline!D57 -> Milestone | E49: =Timeline!E57 -> 42 | F49: =Timeline!F57 -> 42 | G49: =IF(AND(G$4>=$E49,G$4<=$F49),1,"") | H49: =IF(AND(H$4>=$E49,H$4<=$F49),1,"") | I49: =IF(AND(I$4>=$E49,I$4<=$F49),1,"") | J49: =IF(AND(J$4>=$E49,J$4<=$F49),1,"") | K49: =IF(AND(K$4>=$E49,K$4<=$F49),1,"") | L49: =IF(AND(L$4>=$E49,L$4<=$F49),1,"") | M49: =IF(AND(M$4>=$E49,M$4<=$F49),1,"") | N49: =IF(AND(N$4>=$E49,N$4<=$F49),1,"") | ... AV49: =IF(AND(AV$4>=$E49,AV$4<=$F49),1,"") -> 1

Sheet ANU Rules
A1: ANU / RSES rules extracted from the onboarding deck
A3: Area | B3: Requirement (from the deck) | C3: What it means for a 3-year plan | D3: Slide
A4: Program length | B4: Scholarship program end 3.5 yrs; Max Enrolment Period (MEP) 4 yrs (A Dean approves extension); Max Period for Completion (MPC) 5 yrs (PVC Research Training approves). Beyond 4 years, extensions are now more difficult. | C4: Submitting at month 36 leaves ~6 months of scholarship buffer. Do not plan on extensions. | D4: 11-12
A5: First 3 months | B5: ANU requirements: Rights, Relationships & Respect in Research; CORE Cultural Learning; University WHS induction; Code of Conduct. Plus research integrity, RSES induction/WHS, set up supervisory panel. | C5: Finish all compliance items by month 3 so they never block later milestones. | D5: 11-12
A6: Year 1 Plan + Agreement | B6: Yr 1 Plan needs the Candidate-Supervisor Agreement. Many treat it as 'set & forget' but it is a communication tool for every year; paperwork is used if issues escalate to AD(HDR). | C6: Agree feedback turnaround and expectations in writing in month 1-3; revisit yearly. | D6: 11, 18
A7: Confirmation of Candidature (CoC) | B7: A PLAN, not a mid-term review. Goal: check the project is feasible and resources/training are in place. PhD: 9 (-12) months. Aim for the earlier time so the CoC completes on time if amendments are needed. | C7: Target month 9; months 10-12 are the amendment buffer. | D7: 13
A8: CoC written component | B8: Thesis proposal, min 4,000 words, approved by Primary Supervisor, submitted at least 10 working days before the oral. Must include: literature review, methodology, original contribution, initial results, timeline/project plan within program length, resources & funding, accessibility needs (optional), skills assessment. | C8: Have initial results and a realistic 3-year plan ready by month 8. | D8: 14
A9: CoC oral component | B9: 20-30 min presentation + up to 20 min discussion, based on the written proposal, open to all RSES; all CRP members must attend. CRP Chair meets the candidate 1 month prior. Attend RSES seminars. | C9: Book CRP dates early: all panel members must be available. | D9: 13-14
A10: Annual Plan / Report | B10: Yearly eForm: reflect on progress and plans (bullet points, < 2 pages). Discuss with supervisor/Chair and advisory committee before submission; Chair assesses vs previous report; AD(HDR) approves. | C10: Year 2 report ~month 12, Year 3 report ~month 24. | D10: 15-16
A11: Paperwork tip | B11: Submit the RSES annual report at the same time as CoC (or MidTerm Review) and simply refer to it. | C11: If the CoC falls near the annual report date, submit together. | D11: 20
A12: Final stages | B12: Oral presentation to School 6 months before anticipated submission. Notification of Intent to Submit (NOI) and Nomination of Examiners (NOE) about 2 months prior. Pre-submission iThenticate review with supervisor. Submission form + final thesis upload (scholarship ends). Supervisor endorsement. Oral examination mandatory for candidatures that began on/after 1 July 2024. | C12: Final seminar month 30, NOI/NOE month 34, iThenticate month 35, submission month 36. | D12: 17
A13: Progress tracking | B13: Students check ANUHub (selfservice.sas.anu.edu.au); supervisors check ANUHub and eForms. Students are expected to complete milestones on time. | C13: Set calendar reminders from the Timeline dates. | D13: 19
A14: Work hours | B14: 40 hours per week; discuss productivity vs hours and WFH/on-campus with supervisor; AD(HDR) if conflict. Normal hours 08:00-18:00 Mon-Fri; out-of-hours access via Outlook calendar; no work 23:00-06:00. | C14: - | D14: 21
... A22: Key contacts | B22: HDR Administrator Robyne Anderson hdr.cosm@anu.edu.au; AD(HDR) Penny King da.hdr.rses@anu.edu.au; RSES WHS whs.rses@anu.edu.au; Counselling +61 2 6215 2211; ANU Security 02 6125 2249; emergency 000 (0-000 from internal phone). | C22: - | D22: 4, 29-30
